# 异常处理

### do-catch

```swift
/// Swift所有的异常都继承于Error
enum CustomError : Error {
    case exception_1
    case exception_2
    case exception_3
}

class ViewController: UIViewController {

    override func viewDidLoad() {
        super.viewDidLoad()
        
        // 当Swift运行时抛出异常后并没有被处理， 那么程序就会崩溃
        // Swift提供了try、try?、try!、catch、throw、throws关键字处理异常逻辑
        // Swift提供了一种类似于Java try/catch的语法， 是do（函数体内必须有try且该语句可能抛出异常）、catch
        do {
            let str = try self.sayHello(type: 1)
            print(str)
        } catch CustomError.exception_1 {
            print("exception 1")
        } catch CustomError.exception_2 {
            print("exception 2")
        } catch CustomError.exception_3 {
            print("exception 3")
        } catch {
            print("error")
        }
    }
    
    // 声明一个可能抛出异常的函数
    // 在函数后加throws，和Java不同，这里不需要在throws后跟上异常类
    func sayHello(type: Int) throws -> String {
        if type == 1 {
            throw CustomError.exception_1
        }
        if type == 2 {
            throw CustomError.exception_2
        }
        if type == 3 {
            throw CustomError.exception_3
        }
        
        return "Hello world!"
    }
}
```

### try? try!   

`let str = try? self.sayHello(type: 1)`   

相当于  

```swift
let str: String?
do {
    str = try sayHello(type: 1)
} catch {
    str = nil
}
```

try？后面的语句可能会抛出异常， 如果抛出异常则赋值nil给左侧；如果没抛出异常则将返回值赋给左侧; try！取消异常捕获逻辑，语法有点任性，相当于裸奔， 明知可能抛出异常，但自信这段代码不会抛异常。 try！是try？的补充。你确定后面语句不会抛出异常，但真的抛出异常后程序会崩溃。不建议使用try！，有使用场景推荐使用try？  

```swift
let str = try? sayHello(type: 1)  // 如果抛出异常程序正常运行并赋值nil给左侧， 如果没抛异常则将返回值赋给左侧
let str = try! sayHello(type: 1)  // 确定不会抛出异常，但如果运行时抛异常会导致程序崩溃
```

### defer  

Swift使用defer关键字作用同Java的finally

```swift
/// Swift所有的异常都继承于Error
enum CustomError : Error {
    case exception_1
    case exception_2
    case exception_3
}

class ViewController: UIViewController {
    override func viewDidLoad() {
        super.viewDidLoad()
        
        let str = try? self.sayHello(type: 4)
        if let s = str {
            print(s)
        }
    }
 
    func sayHello(type: Int) throws -> String {
        /// 注意defer方法的位置要在throw之前
        defer {
            print("just as finally")
        }

        if type == 1 {
            throw CustomError.exception_1
        }
        if type == 2 {
            throw CustomError.exception_2
        }
        if type == 3 {
            throw CustomError.exception_3
        }
        
        return "Hello world!"
    }
}
```

